Workbook

Sheet Resume
A1: Riskfolio-Lib Report
A2: Copyright (c) 2020-2024, Dany Cajas All rights reserved. Redistribution and use in source and binary forms, with or without modification, are permitted provided that the following conditions are met: * Redistributions of source code must retain the above copyright notice, this list of conditions and the following disclaimer. * Redistributions in binary form must reproduce the above copyright notice, this list of conditions and the following disclaimer in the documentation and/or other materials provided with the distribution. * Neither the name of Riskfolio-Lib nor the names of its contributors may be used to endorse or promote products derived from this software without specific prior written permission. THIS SOFTWARE IS PROVIDED BY THE COPYRIGHT HOLDERS AND CONTRIBUTORS "AS IS" AND ANY EXPRESS OR IMPLIED WARRANTIES, INCLUDING, BUT NOT LIMITED TO, THE IMPLIED WARRANTIES OF MERCHANTABILITY AND FITNESS FOR A PARTICULAR PURPOSE ARE DISCLAIMED. IN NO EVENT SHALL THE COPYRIGHT HOLDER OR CONTRIBUTORS BE LIABLE FOR ANY DIRECT, INDIRECT, INCIDENTAL, SPECIAL, EXEMPLARY, OR CONSEQUENTIAL DAMAGES (INCLUDING, BUT NOT LIMITED TO, PROCUREMENT OF SUBSTITUTE GOODS OR SERVICES; LOSS OF USE, DATA, OR PROFITS; OR BUSINESS INTERRUPTION) HOWEVER CAUSED AND ON ANY THEORY OF LIABILITY, WHETHER IN CONTRACT, STRICT LIABILITY, OR TORT (INCLUDING NEGLIGENCE OR OTHERWISE) ARISING IN ANY WAY OUT OF THE USE OF THIS SOFTWARE, EVEN IF ADVISED OF THE POSSIBILITY OF SUCH DAMAGE.
A3: https://github.com/dcajasn/Riskfolio-Lib
B4: Portfolio 1
A5: Profitability and Other Inputs
A6: Total Days in DataBase | B6: =1453 -> 0
A7: Mean Return (1) | B7: =AVERAGE(Portfolios!$B$2:$B$1004) * 252 -> 0
A8: Compound Annual Growth Rate (CAGR) | B8: {=PRODUCT(1 + Portfolios!$B$2:$B$1004)^(252/1453)-1} -> 0
A9: Minimum Acceptable Return (MAR) (1) | B9: =0 -> 0
A10: Alpha | B10: =0.05 -> 0
A12: Risk Measures based on Returns
A13: Standard Deviation (2) | B13: =STDEV(Portfolios!$B$2:$B$1004) * SQRT(252) -> 0
A14: Mean Absolute Deviation (MAD) (2) | B14: =AVERAGE(Absdev!$B$2:$B$1004) * SQRT(252) -> 0
A15: Semi Standard Deviation (2) | B15: =SQRT(SUMSQ(devBelowMean!$B$2:$B$1004)/(COUNT(devBelowMean!$B$2:$B$1004) - 1)) * SQRT(252) -> 0
A16: First Lower Partial Moment (FLPM) (2) | B16: =AVERAGE(devBelowTarget!$B$2:$B$1004) * SQRT(252) -> 0
A17: Second Lower Partial Moment (SLPM) (2) | B17: =SQRT(SUMSQ(devBelowTarget!$B$2:$B$1004)/(COUNT(devBelowTarget!$B$2:$B$1004) - 1)) * SQRT(252) -> 0
A18: Value at Risk (VaR) (2) | B18: =-SMALL(Portfolios!$B$2:$B$1004,ROUNDUP(COUNT(Portfolios!$B$2:$B$1004)*B10,0)) * SQRT(252) -> 0
A19: Conditional Value at Risk (CVaR) (2) | B19: =-((SUMIF(Portfolios!$B$2:$B$1004,"<="&(-B18/SQRT(252)),Portfolios!$B$2:$B$1004)-ROUNDUP(COUNT(Portfolios!$B$2:$B$1004)*B10,0)*(-B18/SQRT(252)))/(COUNT(Portfolios!$B$2:$B$1004)*B10)-B18/SQRT(252)) * SQRT(252) -> 0
A20: Entropic Value at Risk (EVaR) (2) | B20: =0.025027814137976202 * SQRT(252) -> 0
A21: Worst Realization (2) | B21: =-MIN(Portfolios!$B$2:$B$1004) * SQRT(252) -> 0
A22: Skewness | B22: =SKEW(Portfolios!$B$2:$B$1004) -> 0
A23: Kurtosis | B23: =KURT(Portfolios!$B$2:$B$1004) -> 0
A25: Risk Measures based on Drawdowns (3)
A26: Ulcer Index (UCI) | B26: =SQRT(SUMSQ(Drawdown!$B$2:$B$1004)/COUNT(Drawdown!$B$2:$B$1004)) -> 0
A27: Average Drawdown (ADD) | B27: =AVERAGE(Drawdown!$B$2:$B$1004) -> 0
A28: Drawdown at Risk (DaR) | B28: =+LARGE(Drawdown!$B$2:$B$1004,ROUNDUP(COUNT(Drawdown!$B$2:$B$1004)*B10,0)) -> 0
A29: Conditional Drawdown at Risk (CDaR) | B29: =((SUMIF(Drawdown!$B$2:$B$1004,">="&LARGE(Drawdown!$B$2:$B$1004,ROUNDUP(COUNT(Drawdown!$B$2:$B$1004)*B10,0)),Drawdown!$B$2:$B$1004)-ROUNDUP(COUNT(Drawdown!$B$2:$B$1004)*B10,0)*LARGE(Drawdown!$B$2:$B$1004,ROUNDUP(COUNT(Drawdown!$B$2:$B$1004)*B10,0)))/(COUNT(Drawdown!$B$2:$B$1004)*B10)+LARGE(Drawdown!$B$2:$B$1004,ROUNDUP(COUNT(Drawdown!$B$2:$B$1004)*B10,0))) -> 0
A30: Entropic Drawdown at Risk (CDaR) | B30: =0.10194470229897305 -> 0
A31: Max Drawdown (MDD) | B31: =MAX(Drawdown!$B$2:$B$1004) -> 0
A32: (1) Annualized, multiplied by 252
A33: (2) Annualized, multiplied by √252
A34: (3) Based on uncompounded cumulated returns
B37: Portfolio 1
A38: APA | B38: 7.7600211e-10
A39: BA | B39: 0.055230293
A40: BAX | B40: 0.10293157
A41: BMY | B41: 1.9294346e-09
A42: CMCSA | B42: 8.4345389e-09
A43: CNP | B43: 0.078409206
A44: CPB | B44: 4.2767122e-09
...

Sheet Returns
A1: Date | B1: APA | C1: BA | D1: BAX | E1: BMY | F1: CMCSA | G1: CNP | H1: CPB | I1: DE | J1: HPQ | K1: JCI | L1: JPM | M1: LUV | N1: MO | O1: MRSH | P1: MSFT | Q1: NI | R1: PCAR | S1: PSA | T1: SHW | U1: T | V1: TGT | W1: TMO | X1: TXT | Y1: VZ | Z1: ZION
A2: 42374 | B2: -0.020257172 | C2: 0.0040568573 | D2: 0.004035446 | E2: 0.019692502 | F2: 0.00017929963 | G2: 0.0093051647 | H2: 0.0036780952 | I2: 0.0057827392 | J2: 0.0094824915 | K2: -0.011953327 | L2: 0.0017289776 | M2: 0.011916206 | N2: 0.020212079 | O2: 0.0082843109 | P2: 0.0045620235 | Q2: 0.015880831 | R2: 0.00021204622 | S2: 0.028235772 | T2: 0.0040435087 | U2: 0.0069867397 | V2: 0.017538953 | W2: -0.0017295896 | X2: 0.0024095066 | Y2: 0.013733958 | Z2: -0.010857115
A3: 42375 | B3: -0.11486275 | C3: -0.015878737 | D3: 0.00241156 | E3: -0.017556395 | F3: -0.0077264001 | G3: -0.012473029 | H3: -0.0017361878 | I3: -0.011238452 | J3: -0.035866722 | K3: -0.0095510901 | L3: -0.014435783 | M3: 0.0091848034 | N3: 0.010589566 | O3: -0.012050066 | P3: -0.018165463 | Q3: 0.0055476081 | R3: 0.00021191301 | S3: 0.0015920571 | T3: -0.02893106 | U3: 0.0031081277 | V3: -0.010154987 | W3: -0.0076530044 | X3: -0.030048064 | Y3: -0.0090338155 | Z3: -0.029144747
A4: 42376 | B4: -0.051388787 | C4: -0.041921381 | D4: -0.016573349 | E4: -0.027699238 | F4: -0.011047087 | G4: -0.019769302 | H4: -0.012206225 | I4: -0.0088556287 | J4: -0.046057659 | K4: -0.025394062 | L4: -0.040439372 | M4: -0.021003816 | N4: -0.017407537 | O4: -0.0075773736 | P4: -0.034782425 | Q4: -0.022066464 | R4: -0.030309229 | S4: -0.010410448 | T4: -0.027418047 | U4: -0.016148185 | V4: -0.0026995338 | W4: -0.022844643 | X4: -0.020570126 | Y4: -0.0054925711 | Z4: -0.030019563
A5: 42377 | B5: 0.0027360431 | C5: -0.022705103 | D5: -0.016036691 | E5: -0.02542497 | F5: 0.0010990148 | G5: -0.0022411757 | H5: 0.0057062433 | I5: -0.016402017 | J5: -0.017642305 | K5: -0.0016488329 | L5: -0.022399364 | M5: 0.0061984426 | N5: 0.0017202723 | O5: -0.013966366 | P5: 0.0030672124 | Q5: -0.0015380703 | R5: -0.011366141 | S5: -0.0073077499 | T5: 0.00082835496 | U5: 0.00089509667 | V5: -0.03383894 | W5: -0.0011166555 | X5: -0.011386558 | Y5: -0.0097193159 | Z5: -0.011253793
A6: 42380 | B6: -0.043383442 | C6: 0.0016923757 | D6: -0.016850692 | E6: -0.010215414 | F6: 0.00091435312 | G6: -0.011791104 | H6: 0.0056743005 | I6: 0.0052875732 | J6: 0.0066160713 | K6: 0.00033060293 | L6: -0.0015273522 | M6: -0.004027588 | N6: 0.020947424 | O6: -0.014542001 | P6: -0.00057339613 | Q6: 0.016435525 | R6: 0 | S6: 0.009869252 | T6: 0.00082725071 | U6: 0.012224232 | V6: 0.014570095 | W6: 0.0053664078 | X6: -0.0046071017 | Y6: 0.0057996578 | Z6: -0.019918581
A7: 42381 | B7: 0.010267914 | C7: 0.013132756 | D7: -0.0030909525 | E7: 0.0073038243 | F7: 0.0027409429 | G7: -0.017045474 | H7: 0.040466989 | I7: 0.0049896174 | J7: 0.015962708 | K7: 0.0095770256 | L7: 0.0022095597 | M7: 0.015223228 | N7: -0.0013453777 | O7: 0.0093903086 | P7: 0.0091775059 | Q7: -0.012632829 | R7: -0.00088428545 | S7: 0.0020024738 | T7: 0.018390801 | U7: -0.0014724935 | V7: 0.012980004 | W7: 0.01549567 | X7: 0.0048855766 | Y7: -0.0035484859 | Z7: -0.0041479442
A8: 42382 | B8: 0.0050820952 | C8: -0.028805584 | D8: -0.018320217 | E8: -0.03404786 | F8: -0.024056385 | G8: -0.013294644 | H8: -0.012902269 | I8: -0.017444843 | J8: -0.022181222 | K8: -0.024860983 | L8: -0.027476167 | M8: -0.053420492 | N8: -0.026945051 | O8: -0.0083537919 | P8: -0.02159897 | Q8: -0.003582191 | R8: -0.019694631 | S8: -0.0032776247 | T8: -0.021346117 | U8: -0.0047199314 | V8: -0.023446313 | W8: -0.023362567 | X8: -0.028915042 | Y8: -0.01736025 | Z8: -0.046647144
A9: 42383 | B9: 0.040168116 | C9: 0.0084296816 | D9: 0.0137815 | E9: 0.036390325 | F9: 0.02801107 | G9: 0.032805914 | H9: 0.013259958 | I9: 0.0051896882 | J9: 0.0037808728 | K9: 0.013753516 | L9: 0.01499825 | M9: 0.0017323774 | N9: 0.007614995 | O9: 0.02565543 | P9: 0.028466147 | Q9: 0.027221076 | R9: 0.031828566 | S9: 0.001523983 | T9: 0.0086252142 | U9: 0.01659752 | V9: -0.017168737 | W9: 0.01510009 | X9: 0.0002634188 | Y9: 0.016307939 | Z9: 0.0043686875
A10: 42384 | B10: -0.045908481 | C10: -0.027631602 | D10: -0.0059473901 | E10: -0.011494077 | F10: -0.021071985 | G10: -0.018718078 | H10: -0.0093473628 | I10: -0.0065218593 | J10: -0.048022541 | K10: 0.0023165031 | L10: -0.019931159 | M10: -0.017296608 | N10: -0.017519614 | O10: -0.025387047 | P10: -0.039917017 | Q10: -0.012999748 | R10: -0.0087511781 | S10: -0.0047254134 | T10: -0.0046865416 | U10: -0.009037827 | V10: -0.0046866675 | W10: -0.022313725 | X10: -0.016069823 | Y10: -0.0098059594 | Z10: -0.028273009
A11: 42388 | B11: -0.024058528 | C11: 0.0034229257 | D11: 0.0074074084 | E11: 0.0068490858 | F11: 0.006680411 | G11: 0.011560889 | H11: 0.02528785 | I11: -0.0090260608 | J11: -0.034619164 | K11: 0.0075932741 | L11: -0.00052610354 | M11: -0.0042745836 | N11: 0.020979032 | O11: -0.0011491497 | P11: -0.0084330882 | Q11: 0.015197223 | R11: -0.0061795294 | S11: 0.0076046174 | T11: -0.011359192 | U11: 0.015298526 | V11: -0.011986598 | W11: 0.016194631 | X11: -0.014725133 | Y11: 0.0099030685 | Z11: -0.017904853
A12: 42389 | B12: 0.011100944 | C12: -0.03109643 | D12: -0.016968299 | E12: 0.0053790229 | F12: -0.011796983 | G12: -0.034285978 | H12: -0.0042335391 | I12: -0.0063481463 | J12: -0.021516702 | K12: -0.016328536 | L12: -0.026311337 | M12: -0.0075757983 | N12: -0.020205474 | O12: -0.011697009 | P12: 0.0045490965 | Q12: -0.028942322 | R12: 0.0066623835 | S12: -0.040528724 | T12: 0.025151545 | U12: -0.017675865 | V12: -0.023830149 | W12: -0.013787162 | X12: -0.011956415 | Y12: -0.010028827 | Z12: -0.021422583
A13: 42390 | B13: 0.075989671 | C13: 0.010316191 | D13: 0.014096756 | E13: -0.0066091606 | F13: 0.013243119 | G13: 0.031361052 | H13: -0.00018508105 | I13: 0.014305328 | J13: 0.040837996 | K13: 0.0057012617 | L13: -0.0046836965 | M13: 0.005089123 | N13: 0.004019499 | O13: 0.0011708066 | P13: -0.0061035124 | Q13: 0.0035976064 | R13: 0.01058875 | S13: 0.003204374 | T13: 0.0024454439 | U13: 0.018878722 | V13: 0.015534646 | W13: -0.010297028 | X13: 0.0041256656 | Y13: 0.032642901 | Z13: -0.017698819
... A1004: 43826 | B1004: -0.0057101141 | C1004: 0.00066689135 | D1004: -0.0033203189 | E1004: 0.0028142307 | F1004: 0.0028906884 | G1004: 0 | H1004: 0.0089760771 | I1004: 0.0057780042 | J1004: -0.0077330593 | K1004: -0.0012162114 | L1004: 0.00071903448 | M1004: -0.010564465 | N1004: 0 | O1004: 0.0016988778 | P1004: 0.0018275347 | Q1004: -0.0021939672 | R1004: -0.0012577761 | S1004: 0.0013245835 | T1004: 0.00015475902 | U1004: 0.0020429259 | V1004: 0.0024827472 | W1004: 0.0025787729 | X1004: -0.015316324 | Y1004: 0.0039156433 | Z1004: -0.0030970293

Sheet Portfolios
A1: Date | B1: Portfolio 1
A2: =Returns!A2 -> 0 | B2: {=MMULT(Returns!B2:Z2,Resume!$B$38:$B$62)} -> 0
A3: =Returns!A3 -> 0 | B3: {=MMULT(Returns!B3:Z3,Resume!$B$38:$B$62)} -> 0
A4: =Returns!A4 -> 0 | B4: {=MMULT(Returns!B4:Z4,Resume!$B$38:$B$62)} -> 0
A5: =Returns!A5 -> 0 | B5: {=MMULT(Returns!B5:Z5,Resume!$B$38:$B$62)} -> 0
A6: =Returns!A6 -> 0 | B6: {=MMULT(Returns!B6:Z6,Resume!$B$38:$B$62)} -> 0
A7: =Returns!A7 -> 0 | B7: {=MMULT(Returns!B7:Z7,Resume!$B$38:$B$62)} -> 0
A8: =Returns!A8 -> 0 | B8: {=MMULT(Returns!B8:Z8,Resume!$B$38:$B$62)} -> 0
A9: =Returns!A9 -> 0 | B9: {=MMULT(Returns!B9:Z9,Resume!$B$38:$B$62)} -> 0
A10: =Returns!A10 -> 0 | B10: {=MMULT(Returns!B10:Z10,Resume!$B$38:$B$62)} -> 0
A11: =Returns!A11 -> 0 | B11: {=MMULT(Returns!B11:Z11,Resume!$B$38:$B$62)} -> 0
A12: =Returns!A12 -> 0 | B12: {=MMULT(Returns!B12:Z12,Resume!$B$38:$B$62)} -> 0
A13: =Returns!A13 -> 0 | B13: {=MMULT(Returns!B13:Z13,Resume!$B$38:$B$62)} -> 0
... A1004: =Returns!A1004 -> 0 | B1004: {=MMULT(Returns!B1004:Z1004,Resume!$B$38:$B$62)} -> 0

Sheet Absdev
A1: Date | B1: Portfolio 1
A2: =Returns!A2 -> 0 | B2: =ABS(Portfolios!B2-AVERAGE(Portfolios!$B$2:$B$1004)) -> 0
A3: =Returns!A3 -> 0 | B3: =ABS(Portfolios!B3-AVERAGE(Portfolios!$B$2:$B$1004)) -> 0
A4: =Returns!A4 -> 0 | B4: =ABS(Portfolios!B4-AVERAGE(Portfolios!$B$2:$B$1004)) -> 0
A5: =Returns!A5 -> 0 | B5: =ABS(Portfolios!B5-AVERAGE(Portfolios!$B$2:$B$1004)) -> 0
A6: =Returns!A6 -> 0 | B6: =ABS(Portfolios!B6-AVERAGE(Portfolios!$B$2:$B$1004)) -> 0
A7: =Returns!A7 -> 0 | B7: =ABS(Portfolios!B7-AVERAGE(Portfolios!$B$2:$B$1004)) -> 0
A8: =Returns!A8 -> 0 | B8: =ABS(Portfolios!B8-AVERAGE(Portfolios!$B$2:$B$1004)) -> 0
A9: =Returns!A9 -> 0 | B9: =ABS(Portfolios!B9-AVERAGE(Portfolios!$B$2:$B$1004)) -> 0
A10: =Returns!A10 -> 0 | B10: =ABS(Portfolios!B10-AVERAGE(Portfolios!$B$2:$B$1004)) -> 0
A11: =Returns!A11 -> 0 | B11: =ABS(Portfolios!B11-AVERAGE(Portfolios!$B$2:$B$1004)) -> 0
A12: =Returns!A12 -> 0 | B12: =ABS(Portfolios!B12-AVERAGE(Portfolios!$B$2:$B$1004)) -> 0
A13: =Returns!A13 -> 0 | B13: =ABS(Portfolios!B13-AVERAGE(Portfolios!$B$2:$B$1004)) -> 0
... A1004: =Returns!A1004 -> 0 | B1004: =ABS(Portfolios!B1004-AVERAGE(Portfolios!$B$2:$B$1004)) -> 0

Sheet CumRet
A1: Date | B1: Portfolio 1
A2: =Returns!A2 -> 0 | B2: =SUM(Portfolios!$B$2) -> 0
A3: =Returns!A3 -> 0 | B3: =SUM(Portfolios!$B$2:$B$3) -> 0
A4: =Returns!A4 -> 0 | B4: =SUM(Portfolios!$B$2:$B$4) -> 0
A5: =Returns!A5 -> 0 | B5: =SUM(Portfolios!$B$2:$B$5) -> 0
A6: =Returns!A6 -> 0 | B6: =SUM(Portfolios!$B$2:$B$6) -> 0
A7: =Returns!A7 -> 0 | B7: =SUM(Portfolios!$B$2:$B$7) -> 0
A8: =Returns!A8 -> 0 | B8: =SUM(Portfolios!$B$2:$B$8) -> 0
A9: =Returns!A9 -> 0 | B9: =SUM(Portfolios!$B$2:$B$9) -> 0
A10: =Returns!A10 -> 0 | B10: =SUM(Portfolios!$B$2:$B$10) -> 0
A11: =Returns!A11 -> 0 | B11: =SUM(Portfolios!$B$2:$B$11) -> 0
A12: =Returns!A12 -> 0 | B12: =SUM(Portfolios!$B$2:$B$12) -> 0
A13: =Returns!A13 -> 0 | B13: =SUM(Portfolios!$B$2:$B$13) -> 0
A14: =Returns!A14 -> 0 | B14: =SUM(Portfolios!$B$2:$B$14) -> 0
A15: =Returns!A15 -> 0 | B15: =SUM(Portfolios!$B$2:$B$15) -> 0
A16: =Returns!A16 -> 0 | B16: =SUM(Portfolios!$B$2:$B$16) -> 0
A17: =Returns!A17 -> 0 | B17: =SUM(Portfolios!$B$2:$B$17) -> 0
A18: =Returns!A18 -> 0 | B18: =SUM(Portfolios!$B$2:$B$18) -> 0
A19: =Returns!A19 -> 0 | B19: =SUM(Portfolios!$B$2:$B$19) -> 0
A20: =Returns!A20 -> 0 | B20: =SUM(Portfolios!$B$2:$B$20) -> 0
A21: =Returns!A21 -> 0 | B21: =SUM(Portfolios!$B$2:$B$21) -> 0
A22: =Returns!A22 -> 0 | B22: =SUM(Portfolios!$B$2:$B$22) -> 0
A23: =Returns!A23 -> 0 | B23: =SUM(Portfolios!$B$2:$B$23) -> 0
A24: =Returns!A24 -> 0 | B24: =SUM(Portfolios!$B$2:$B$24) -> 0
A25: =Returns!A25 -> 0 | B25: =SUM(Portfolios!$B$2:$B$25) -> 0
A26: =Returns!A26 -> 0 | B26: =SUM(Portfolios!$B$2:$B$26) -> 0
A27: =Returns!A27 -> 0 | B27: =SUM(Portfolios!$B$2:$B$27) -> 0
A28: =Returns!A28 -> 0 | B28: =SUM(Portfolios!$B$2:$B$28) -> 0
A29: =Returns!A29 -> 0 | B29: =SUM(Portfolios!$B$2:$B$29) -> 0
A30: =Returns!A30 -> 0 | B30: =SUM(Portfolios!$B$2:$B$30) -> 0
A31: =Returns!A31 -> 0 | B31: =SUM(Portfolios!$B$2:$B$31) -> 0
A32: =Returns!A32 -> 0 | B32: =SUM(Portfolios!$B$2:$B$32) -> 0
A33: =Returns!A33 -> 0 | B33: =SUM(Portfolios!$B$2:$B$33) -> 0
A34: =Returns!A34 -> 0 | B34: =SUM(Portfolios!$B$2:$B$34) -> 0
A35: =Returns!A35 -> 0 | B35: =SUM(Portfolios!$B$2:$B$35) -> 0
A36: =Returns!A36 -> 0 | B36: =SUM(Portfolios!$B$2:$B$36) -> 0
A37: =Returns!A37 -> 0 | B37: =SUM(Portfolios!$B$2:$B$37) -> 0
A38: =Returns!A38 -> 0 | B38: =SUM(Portfolios!$B$2:$B$38) -> 0
A39: =Returns!A39 -> 0 | B39: =SUM(Portfolios!$B$2:$B$39) -> 0
A40: =Returns!A40 -> 0 | B40: =SUM(Portfolios!$B$2:$B$40) -> 0
...

Sheet Drawdown
A1: Date | B1: Portfolio 1
A2: =Returns!A2 -> 0 | B2: =MAX(CumRet!$B$2)-CumRet!B2 -> 0
A3: =Returns!A3 -> 0 | B3: =MAX(CumRet!$B$2:$B$3)-CumRet!B3 -> 0
A4: =Returns!A4 -> 0 | B4: =MAX(CumRet!$B$2:$B$4)-CumRet!B4 -> 0
A5: =Returns!A5 -> 0 | B5: =MAX(CumRet!$B$2:$B$5)-CumRet!B5 -> 0
A6: =Returns!A6 -> 0 | B6: =MAX(CumRet!$B$2:$B$6)-CumRet!B6 -> 0
A7: =Returns!A7 -> 0 | B7: =MAX(CumRet!$B$2:$B$7)-CumRet!B7 -> 0
A8: =Returns!A8 -> 0 | B8: =MAX(CumRet!$B$2:$B$8)-CumRet!B8 -> 0
A9: =Returns!A9 -> 0 | B9: =MAX(CumRet!$B$2:$B$9)-CumRet!B9 -> 0
A10: =Returns!A10 -> 0 | B10: =MAX(CumRet!$B$2:$B$10)-CumRet!B10 -> 0
A11: =Returns!A11 -> 0 | B11: =MAX(CumRet!$B$2:$B$11)-CumRet!B11 -> 0
A12: =Returns!A12 -> 0 | B12: =MAX(CumRet!$B$2:$B$12)-CumRet!B12 -> 0
A13: =Returns!A13 -> 0 | B13: =MAX(CumRet!$B$2:$B$13)-CumRet!B13 -> 0
A14: =Returns!A14 -> 0 | B14: =MAX(CumRet!$B$2:$B$14)-CumRet!B14 -> 0
A15: =Returns!A15 -> 0 | B15: =MAX(CumRet!$B$2:$B$15)-CumRet!B15 -> 0
A16: =Returns!A16 -> 0 | B16: =MAX(CumRet!$B$2:$B$16)-CumRet!B16 -> 0
A17: =Returns!A17 -> 0 | B17: =MAX(CumRet!$B$2:$B$17)-CumRet!B17 -> 0
A18: =Returns!A18 -> 0 | B18: =MAX(CumRet!$B$2:$B$18)-CumRet!B18 -> 0
A19: =Returns!A19 -> 0 | B19: =MAX(CumRet!$B$2:$B$19)-CumRet!B19 -> 0
A20: =Returns!A20 -> 0 | B20: =MAX(CumRet!$B$2:$B$20)-CumRet!B20 -> 0
A21: =Returns!A21 -> 0 | B21: =MAX(CumRet!$B$2:$B$21)-CumRet!B21 -> 0
A22: =Returns!A22 -> 0 | B22: =MAX(CumRet!$B$2:$B$22)-CumRet!B22 -> 0
A23: =Returns!A23 -> 0 | B23: =MAX(CumRet!$B$2:$B$23)-CumRet!B23 -> 0
A24: =Returns!A24 -> 0 | B24: =MAX(CumRet!$B$2:$B$24)-CumRet!B24 -> 0
A25: =Returns!A25 -> 0 | B25: =MAX(CumRet!$B$2:$B$25)-CumRet!B25 -> 0
A26: =Returns!A26 -> 0 | B26: =MAX(CumRet!$B$2:$B$26)-CumRet!B26 -> 0
A27: =Returns!A27 -> 0 | B27: =MAX(CumRet!$B$2:$B$27)-CumRet!B27 -> 0
A28: =Returns!A28 -> 0 | B28: =MAX(CumRet!$B$2:$B$28)-CumRet!B28 -> 0
A29: =Returns!A29 -> 0 | B29: =MAX(CumRet!$B$2:$B$29)-CumRet!B29 -> 0
A30: =Returns!A30 -> 0 | B30: =MAX(CumRet!$B$2:$B$30)-CumRet!B30 -> 0
A31: =Returns!A31 -> 0 | B31: =MAX(CumRet!$B$2:$B$31)-CumRet!B31 -> 0
A32: =Returns!A32 -> 0 | B32: =MAX(CumRet!$B$2:$B$32)-CumRet!B32 -> 0
A33: =Returns!A33 -> 0 | B33: =MAX(CumRet!$B$2:$B$33)-CumRet!B33 -> 0
A34: =Returns!A34 -> 0 | B34: =MAX(CumRet!$B$2:$B$34)-CumRet!B34 -> 0
A35: =Returns!A35 -> 0 | B35: =MAX(CumRet!$B$2:$B$35)-CumRet!B35 -> 0
A36: =Returns!A36 -> 0 | B36: =MAX(CumRet!$B$2:$B$36)-CumRet!B36 -> 0
A37: =Returns!A37 -> 0 | B37: =MAX(CumRet!$B$2:$B$37)-CumRet!B37 -> 0
A38: =Returns!A38 -> 0 | B38: =MAX(CumRet!$B$2:$B$38)-CumRet!B38 -> 0
A39: =Returns!A39 -> 0 | B39: =MAX(CumRet!$B$2:$B$39)-CumRet!B39 -> 0
A40: =Returns!A40 -> 0 | B40: =MAX(CumRet!$B$2:$B$40)-CumRet!B40 -> 0
...

Sheet devBelowTarget
A1: Date | B1: Portfolio 1
A2: =Returns!A2 -> 0 | B2: =MAX(Resume!B9/ 252-Portfolios!B2, 0) -> 0
A3: =Returns!A3 -> 0 | B3: =MAX(Resume!B9/ 252-Portfolios!B3, 0) -> 0
A4: =Returns!A4 -> 0 | B4: =MAX(Resume!B9/ 252-Portfolios!B4, 0) -> 0
A5: =Returns!A5 -> 0 | B5: =MAX(Resume!B9/ 252-Portfolios!B5, 0) -> 0
A6: =Returns!A6 -> 0 | B6: =MAX(Resume!B9/ 252-Portfolios!B6, 0) -> 0
A7: =Returns!A7 -> 0 | B7: =MAX(Resume!B9/ 252-Portfolios!B7, 0) -> 0
A8: =Returns!A8 -> 0 | B8: =MAX(Resume!B9/ 252-Portfolios!B8, 0) -> 0
A9: =Returns!A9 -> 0 | B9: =MAX(Resume!B9/ 252-Portfolios!B9, 0) -> 0
A10: =Returns!A10 -> 0 | B10: =MAX(Resume!B9/ 252-Portfolios!B10, 0) -> 0
A11: =Returns!A11 -> 0 | B11: =MAX(Resume!B9/ 252-Portfolios!B11, 0) -> 0
A12: =Returns!A12 -> 0 | B12: =MAX(Resume!B9/ 252-Portfolios!B12, 0) -> 0
A13: =Returns!A13 -> 0 | B13: =MAX(Resume!B9/ 252-Portfolios!B13, 0) -> 0
A14: =Returns!A14 -> 0 | B14: =MAX(Resume!B9/ 252-Portfolios!B14, 0) -> 0
A15: =Returns!A15 -> 0 | B15: =MAX(Resume!B9/ 252-Portfolios!B15, 0) -> 0
A16: =Returns!A16 -> 0 | B16: =MAX(Resume!B9/ 252-Portfolios!B16, 0) -> 0
A17: =Returns!A17 -> 0 | B17: =MAX(Resume!B9/ 252-Portfolios!B17, 0) -> 0
A18: =Returns!A18 -> 0 | B18: =MAX(Resume!B9/ 252-Portfolios!B18, 0) -> 0
A19: =Returns!A19 -> 0 | B19: =MAX(Resume!B9/ 252-Portfolios!B19, 0) -> 0
A20: =Returns!A20 -> 0 | B20: =MAX(Resume!B9/ 252-Portfolios!B20, 0) -> 0
A21: =Returns!A21 -> 0 | B21: =MAX(Resume!B9/ 252-Portfolios!B21, 0) -> 0
A22: =Returns!A22 -> 0 | B22: =MAX(Resume!B9/ 252-Portfolios!B22, 0) -> 0
A23: =Returns!A23 -> 0 | B23: =MAX(Resume!B9/ 252-Portfolios!B23, 0) -> 0
A24: =Returns!A24 -> 0 | B24: =MAX(Resume!B9/ 252-Portfolios!B24, 0) -> 0
A25: =Returns!A25 -> 0 | B25: =MAX(Resume!B9/ 252-Portfolios!B25, 0) -> 0
A26: =Returns!A26 -> 0 | B26: =MAX(Resume!B9/ 252-Portfolios!B26, 0) -> 0
A27: =Returns!A27 -> 0 | B27: =MAX(Resume!B9/ 252-Portfolios!B27, 0) -> 0
A28: =Returns!A28 -> 0 | B28: =MAX(Resume!B9/ 252-Portfolios!B28, 0) -> 0
A29: =Returns!A29 -> 0 | B29: =MAX(Resume!B9/ 252-Portfolios!B29, 0) -> 0
A30: =Returns!A30 -> 0 | B30: =MAX(Resume!B9/ 252-Portfolios!B30, 0) -> 0
A31: =Returns!A31 -> 0 | B31: =MAX(Resume!B9/ 252-Portfolios!B31, 0) -> 0
A32: =Returns!A32 -> 0 | B32: =MAX(Resume!B9/ 252-Portfolios!B32, 0) -> 0
A33: =Returns!A33 -> 0 | B33: =MAX(Resume!B9/ 252-Portfolios!B33, 0) -> 0
A34: =Returns!A34 -> 0 | B34: =MAX(Resume!B9/ 252-Portfolios!B34, 0) -> 0
A35: =Returns!A35 -> 0 | B35: =MAX(Resume!B9/ 252-Portfolios!B35, 0) -> 0
A36: =Returns!A36 -> 0 | B36: =MAX(Resume!B9/ 252-Portfolios!B36, 0) -> 0
A37: =Returns!A37 -> 0 | B37: =MAX(Resume!B9/ 252-Portfolios!B37, 0) -> 0
A38: =Returns!A38 -> 0 | B38: =MAX(Resume!B9/ 252-Portfolios!B38, 0) -> 0
A39: =Returns!A39 -> 0 | B39: =MAX(Resume!B9/ 252-Portfolios!B39, 0) -> 0
A40: =Returns!A40 -> 0 | B40: =MAX(Resume!B9/ 252-Portfolios!B40, 0) -> 0
...

Sheet devBelowMean
A1: Date | B1: Portfolio 1
A2: =Returns!A2 -> 0 | B2: =MAX(AVERAGE(Portfolios!$B$2:$B$1004)-Portfolios!B2, 0) -> 0
A3: =Returns!A3 -> 0 | B3: =MAX(AVERAGE(Portfolios!$B$2:$B$1004)-Portfolios!B3, 0) -> 0
A4: =Returns!A4 -> 0 | B4: =MAX(AVERAGE(Portfolios!$B$2:$B$1004)-Portfolios!B4, 0) -> 0
A5: =Returns!A5 -> 0 | B5: =MAX(AVERAGE(Portfolios!$B$2:$B$1004)-Portfolios!B5, 0) -> 0
A6: =Returns!A6 -> 0 | B6: =MAX(AVERAGE(Portfolios!$B$2:$B$1004)-Portfolios!B6, 0) -> 0
A7: =Returns!A7 -> 0 | B7: =MAX(AVERAGE(Portfolios!$B$2:$B$1004)-Portfolios!B7, 0) -> 0
A8: =Returns!A8 -> 0 | B8: =MAX(AVERAGE(Portfolios!$B$2:$B$1004)-Portfolios!B8, 0) -> 0
A9: =Returns!A9 -> 0 | B9: =MAX(AVERAGE(Portfolios!$B$2:$B$1004)-Portfolios!B9, 0) -> 0
A10: =Returns!A10 -> 0 | B10: =MAX(AVERAGE(Portfolios!$B$2:$B$1004)-Portfolios!B10, 0) -> 0
A11: =Returns!A11 -> 0 | B11: =MAX(AVERAGE(Portfolios!$B$2:$B$1004)-Portfolios!B11, 0) -> 0
A12: =Returns!A12 -> 0 | B12: =MAX(AVERAGE(Portfolios!$B$2:$B$1004)-Portfolios!B12, 0) -> 0
A13: =Returns!A13 -> 0 | B13: =MAX(AVERAGE(Portfolios!$B$2:$B$1004)-Portfolios!B13, 0) -> 0
... A1004: =Returns!A1004 -> 0 | B1004: =MAX(AVERAGE(Portfolios!$B$2:$B$1004)-Portfolios!B1004, 0) -> 0
